Traceback (most recent call last):
  File "/Users/caballero/repos/open-physics-ed/modern-mathematical-methods/.venv/lib/python3.13/site-packages/jupyter_core/utils/__init__.py", line 154, in wrapped
    asyncio.get_running_loop()
    ~~~~~~~~~~~~~~~~~~~~~~~~^^
RuntimeError: no running event loop

During handling of the above exception, another exception occurred:

Traceback (most recent call last):
  File "/Users/caballero/repos/open-physics-ed/modern-mathematical-methods/.venv/lib/python3.13/site-packages/jupyter_cache/executors/utils.py", line 58, in single_nb_execution
    executenb(
    ~~~~~~~~~^
        nb,
        ^^^
    ...<4 lines>...
        **kwargs,
        ^^^^^^^^^
    )
    ^
  File "/Users/caballero/repos/open-physics-ed/modern-mathematical-methods/.venv/lib/python3.13/site-packages/nbclient/client.py", line 1319, in execute
    return NotebookClient(nb=nb, resources=resources, km=km, **kwargs).execute()
           ~~~~~~~~~~~~~~~~~~~~~~~~~~~~~~~~~~~~~~~~~~~~~~~~~~~~~~~~~~~~~~~~~~~^^
  File "/Users/caballero/repos/open-physics-ed/modern-mathematical-methods/.venv/lib/python3.13/site-packages/jupyter_core/utils/__init__.py", line 158, in wrapped
    return loop.run_until_complete(inner)
           ~~~~~~~~~~~~~~~~~~~~~~~^^^^^^^
  File "/opt/homebrew/Cellar/python@3.13/3.13.5/Frameworks/Python.framework/Versions/3.13/lib/python3.13/asyncio/base_events.py", line 725, in run_until_complete
    return future.result()
           ~~~~~~~~~~~~~^^
  File "/Users/caballero/repos/open-physics-ed/modern-mathematical-methods/.venv/lib/python3.13/site-packages/nbclient/client.py", line 709, in async_execute
    await self.async_execute_cell(
        cell, index, execution_count=self.code_cells_executed + 1
    )
  File "/Users/caballero/repos/open-physics-ed/modern-mathematical-methods/.venv/lib/python3.13/site-packages/nbclient/client.py", line 1062, in async_execute_cell
    await self._check_raise_for_error(cell, cell_index, exec_reply)
  File "/Users/caballero/repos/open-physics-ed/modern-mathematical-methods/.venv/lib/python3.13/site-packages/nbclient/client.py", line 918, in _check_raise_for_error
    raise CellExecutionError.from_cell_and_msg(cell, exec_reply_content)
nbclient.exceptions.CellExecutionError: An error occurred while executing the following cell:
------------------
import numpy as np
import matplotlib.pyplot as plt
from scipy.integrate import solve_ivp

def VP_eqn(x, v, mu = 1.):
    xdot, vdot = [0,0] ## CHANGE
    return xdot, vdot

def VP_phase(X, VX, mu):
    xdot, vdot = np.zeros(X.shape), np.zeros(VX.shape)
    Xlim, Ylim = X.shape
    for i in range(Xlim):
        for j in range(Ylim):
            xloc = X[i, j]
            yloc = VX[i, j]
            xdot[i,j], vdot[i,j] = VP_eqn(xloc, yloc,mu)
    return xdot, vdot

def VP_eqn_for_solve_ivp(t,curr_vals, mu=1): # need to rephrase this to work with what solve_ivp expects
    x, v = curr_vals 
    xdot, vdot = VP_eqn(x,v,mu)
    return xdot,vdot

# Numerical Integration
tmax = 20
dt = 0.05
tspan = (0,tmax)
t = np.arange(0,tmax,dt)
mu = 1.
initial_condition = [1, 1] 
solved = solve_ivp(VP_eqn_for_solve_ivp,tspan,initial_condition,t_eval = t, args = (mu,),method="RK45")


# Plotting stuff
N = 40
x = np.linspace(-3., 3., N)
v = np.linspace(-3., 3., N)
X, V = np.meshgrid(x, v)
xdot, vdot = VP_phase(X, V,mu)
ax = plt.figure(figsize=(10,10))
Q = plt.streamplot(X, V, xdot, vdot, color='k',broken_streamlines = False)
plt.plot(solved.y[0],solved.y[1],lw = 3,c = 'red') # plot trajectory from solve_ivp
plt.grid()
plt.xlabel('$x$')
plt.ylabel('$v$')
plt.show()
------------------


[0;31m---------------------------------------------------------------------------[0m
[0;31mModuleNotFoundError[0m                       Traceback (most recent call last)
Cell [0;32mIn[1], line 1[0m
[0;32m----> 1[0m [38;5;28;01mimport[39;00m[38;5;250m [39m[38;5;21;01mnumpy[39;00m[38;5;250m [39m[38;5;28;01mas[39;00m[38;5;250m [39m[38;5;21;01mnp[39;00m
[1;32m      2[0m [38;5;28;01mimport[39;00m[38;5;250m [39m[38;5;21;01mmatplotlib[39;00m[38;5;21;01m.[39;00m[38;5;21;01mpyplot[39;00m[38;5;250m [39m[38;5;28;01mas[39;00m[38;5;250m [39m[38;5;21;01mplt[39;00m
[1;32m      3[0m [38;5;28;01mfrom[39;00m[38;5;250m [39m[38;5;21;01mscipy[39;00m[38;5;21;01m.[39;00m[38;5;21;01mintegrate[39;00m[38;5;250m [39m[38;5;28;01mimport[39;00m solve_ivp

[0;31mModuleNotFoundError[0m: No module named 'numpy'

