Traceback (most recent call last):
  File "/Users/caballero/repos/open-physics-ed/modern-mathematical-methods/.venv/lib/python3.13/site-packages/jupyter_core/utils/__init__.py", line 154, in wrapped
    asyncio.get_running_loop()
    ~~~~~~~~~~~~~~~~~~~~~~~~^^
RuntimeError: no running event loop

During handling of the above exception, another exception occurred:

Traceback (most recent call last):
  File "/Users/caballero/repos/open-physics-ed/modern-mathematical-methods/.venv/lib/python3.13/site-packages/jupyter_cache/executors/utils.py", line 58, in single_nb_execution
    executenb(
    ~~~~~~~~~^
        nb,
        ^^^
    ...<4 lines>...
        **kwargs,
        ^^^^^^^^^
    )
    ^
  File "/Users/caballero/repos/open-physics-ed/modern-mathematical-methods/.venv/lib/python3.13/site-packages/nbclient/client.py", line 1319, in execute
    return NotebookClient(nb=nb, resources=resources, km=km, **kwargs).execute()
           ~~~~~~~~~~~~~~~~~~~~~~~~~~~~~~~~~~~~~~~~~~~~~~~~~~~~~~~~~~~~~~~~~~~^^
  File "/Users/caballero/repos/open-physics-ed/modern-mathematical-methods/.venv/lib/python3.13/site-packages/jupyter_core/utils/__init__.py", line 158, in wrapped
    return loop.run_until_complete(inner)
           ~~~~~~~~~~~~~~~~~~~~~~~^^^^^^^
  File "/opt/homebrew/Cellar/python@3.13/3.13.5/Frameworks/Python.framework/Versions/3.13/lib/python3.13/asyncio/base_events.py", line 725, in run_until_complete
    return future.result()
           ~~~~~~~~~~~~~^^
  File "/Users/caballero/repos/open-physics-ed/modern-mathematical-methods/.venv/lib/python3.13/site-packages/nbclient/client.py", line 709, in async_execute
    await self.async_execute_cell(
        cell, index, execution_count=self.code_cells_executed + 1
    )
  File "/Users/caballero/repos/open-physics-ed/modern-mathematical-methods/.venv/lib/python3.13/site-packages/nbclient/client.py", line 1062, in async_execute_cell
    await self._check_raise_for_error(cell, cell_index, exec_reply)
  File "/Users/caballero/repos/open-physics-ed/modern-mathematical-methods/.venv/lib/python3.13/site-packages/nbclient/client.py", line 918, in _check_raise_for_error
    raise CellExecutionError.from_cell_and_msg(cell, exec_reply_content)
nbclient.exceptions.CellExecutionError: An error occurred while executing the following cell:
------------------
from sympy import symbols, latex, init_printing, Rational
from sympy.interactive import printing

# Setup LaTeX printing
init_printing(use_latex=True)

# Define variables
k, q, r = symbols('k q r')

# Define electric potential equation for point charge
V = k * q / r

# Print the equation in LaTeX format
display(V)
------------------


[0;31m---------------------------------------------------------------------------[0m
[0;31mModuleNotFoundError[0m                       Traceback (most recent call last)
Cell [0;32mIn[1], line 1[0m
[0;32m----> 1[0m [38;5;28;01mfrom[39;00m[38;5;250m [39m[38;5;21;01msympy[39;00m[38;5;250m [39m[38;5;28;01mimport[39;00m symbols, latex, init_printing, Rational
[1;32m      2[0m [38;5;28;01mfrom[39;00m[38;5;250m [39m[38;5;21;01msympy[39;00m[38;5;21;01m.[39;00m[38;5;21;01minteractive[39;00m[38;5;250m [39m[38;5;28;01mimport[39;00m printing
[1;32m      4[0m [38;5;66;03m# Setup LaTeX printing[39;00m

[0;31mModuleNotFoundError[0m: No module named 'sympy'

